2020-09-09 09:02:28,219 - root - ERROR : Error: 数据库连接时发生错误, 信息: (2003, "Can't connect to MySQL server on 'rm-uf63c1mgv7c7b80a4.mysql.rds.aliyuncs.com' (timed out)")
Traceback (most recent call last):
  File "E:\WorkZoom\apiFlowAutoTest\venv\lib\site-packages\pymysql\connections.py", line 571, in connect
    **kwargs)
  File "D:\Program Files\Python\lib\socket.py", line 728, in create_connection
    raise err
  File "D:\Program Files\Python\lib\socket.py", line 716, in create_connection
    sock.connect(sa)
socket.timeout: timed out

During handling of the above exception, another exception occurred:

Traceback (most recent call last):
  File "E:\WorkZoom\apiFlowAutoTest\common\config_db.py", line 23, in connect_db
    self.db = pymysql.connect(host=self.host, port=int(self.port), user=self.user, password=self.password)
  File "E:\WorkZoom\apiFlowAutoTest\venv\lib\site-packages\pymysql\__init__.py", line 94, in Connect
    return Connection(*args, **kwargs)
  File "E:\WorkZoom\apiFlowAutoTest\venv\lib\site-packages\pymysql\connections.py", line 327, in __init__
    self.connect()
  File "E:\WorkZoom\apiFlowAutoTest\venv\lib\site-packages\pymysql\connections.py", line 619, in connect
    raise exc
pymysql.err.OperationalError: (2003, "Can't connect to MySQL server on 'rm-uf63c1mgv7c7b80a4.mysql.rds.aliyuncs.com' (timed out)")
2020-09-09 09:02:38,305 - root - ERROR : Error: 数据库连接时发生错误, 信息: (2003, "Can't connect to MySQL server on 'rm-uf63c1mgv7c7b80a4.mysql.rds.aliyuncs.com' (timed out)")
Traceback (most recent call last):
  File "E:\WorkZoom\apiFlowAutoTest\venv\lib\site-packages\pymysql\connections.py", line 571, in connect
    **kwargs)
  File "D:\Program Files\Python\lib\socket.py", line 728, in create_connection
    raise err
  File "D:\Program Files\Python\lib\socket.py", line 716, in create_connection
    sock.connect(sa)
socket.timeout: timed out

During handling of the above exception, another exception occurred:

Traceback (most recent call last):
  File "E:\WorkZoom\apiFlowAutoTest\common\config_db.py", line 23, in connect_db
    self.db = pymysql.connect(host=self.host, port=int(self.port), user=self.user, password=self.password)
  File "E:\WorkZoom\apiFlowAutoTest\venv\lib\site-packages\pymysql\__init__.py", line 94, in Connect
    return Connection(*args, **kwargs)
  File "E:\WorkZoom\apiFlowAutoTest\venv\lib\site-packages\pymysql\connections.py", line 327, in __init__
    self.connect()
  File "E:\WorkZoom\apiFlowAutoTest\venv\lib\site-packages\pymysql\connections.py", line 619, in connect
    raise exc
pymysql.err.OperationalError: (2003, "Can't connect to MySQL server on 'rm-uf63c1mgv7c7b80a4.mysql.rds.aliyuncs.com' (timed out)")
2020-09-09 09:02:48,368 - root - ERROR : Error: 数据库连接时发生错误, 信息: (2003, "Can't connect to MySQL server on 'rm-uf63c1mgv7c7b80a4.mysql.rds.aliyuncs.com' (timed out)")
Traceback (most recent call last):
  File "E:\WorkZoom\apiFlowAutoTest\venv\lib\site-packages\pymysql\connections.py", line 571, in connect
    **kwargs)
  File "D:\Program Files\Python\lib\socket.py", line 728, in create_connection
    raise err
  File "D:\Program Files\Python\lib\socket.py", line 716, in create_connection
    sock.connect(sa)
socket.timeout: timed out

During handling of the above exception, another exception occurred:

Traceback (most recent call last):
  File "E:\WorkZoom\apiFlowAutoTest\common\config_db.py", line 23, in connect_db
    self.db = pymysql.connect(host=self.host, port=int(self.port), user=self.user, password=self.password)
  File "E:\WorkZoom\apiFlowAutoTest\venv\lib\site-packages\pymysql\__init__.py", line 94, in Connect
    return Connection(*args, **kwargs)
  File "E:\WorkZoom\apiFlowAutoTest\venv\lib\site-packages\pymysql\connections.py", line 327, in __init__
    self.connect()
  File "E:\WorkZoom\apiFlowAutoTest\venv\lib\site-packages\pymysql\connections.py", line 619, in connect
    raise exc
pymysql.err.OperationalError: (2003, "Can't connect to MySQL server on 'rm-uf63c1mgv7c7b80a4.mysql.rds.aliyuncs.com' (timed out)")
2020-09-09 09:02:58,425 - root - ERROR : Error: 数据库连接时发生错误, 信息: (2003, "Can't connect to MySQL server on 'rm-uf63c1mgv7c7b80a4.mysql.rds.aliyuncs.com' (timed out)")
Traceback (most recent call last):
  File "E:\WorkZoom\apiFlowAutoTest\venv\lib\site-packages\pymysql\connections.py", line 571, in connect
    **kwargs)
  File "D:\Program Files\Python\lib\socket.py", line 728, in create_connection
    raise err
  File "D:\Program Files\Python\lib\socket.py", line 716, in create_connection
    sock.connect(sa)
socket.timeout: timed out

During handling of the above exception, another exception occurred:

Traceback (most recent call last):
  File "E:\WorkZoom\apiFlowAutoTest\common\config_db.py", line 23, in connect_db
    self.db = pymysql.connect(host=self.host, port=int(self.port), user=self.user, password=self.password)
  File "E:\WorkZoom\apiFlowAutoTest\venv\lib\site-packages\pymysql\__init__.py", line 94, in Connect
    return Connection(*args, **kwargs)
  File "E:\WorkZoom\apiFlowAutoTest\venv\lib\site-packages\pymysql\connections.py", line 327, in __init__
    self.connect()
  File "E:\WorkZoom\apiFlowAutoTest\venv\lib\site-packages\pymysql\connections.py", line 619, in connect
    raise exc
pymysql.err.OperationalError: (2003, "Can't connect to MySQL server on 'rm-uf63c1mgv7c7b80a4.mysql.rds.aliyuncs.com' (timed out)")
2020-09-09 09:03:08,487 - root - ERROR : Error: 数据库连接时发生错误, 信息: (2003, "Can't connect to MySQL server on 'rm-uf63c1mgv7c7b80a4.mysql.rds.aliyuncs.com' (timed out)")
Traceback (most recent call last):
  File "E:\WorkZoom\apiFlowAutoTest\venv\lib\site-packages\pymysql\connections.py", line 571, in connect
    **kwargs)
  File "D:\Program Files\Python\lib\socket.py", line 728, in create_connection
    raise err
  File "D:\Program Files\Python\lib\socket.py", line 716, in create_connection
    sock.connect(sa)
socket.timeout: timed out

During handling of the above exception, another exception occurred:

Traceback (most recent call last):
  File "E:\WorkZoom\apiFlowAutoTest\common\config_db.py", line 23, in connect_db
    self.db = pymysql.connect(host=self.host, port=int(self.port), user=self.user, password=self.password)
  File "E:\WorkZoom\apiFlowAutoTest\venv\lib\site-packages\pymysql\__init__.py", line 94, in Connect
    return Connection(*args, **kwargs)
  File "E:\WorkZoom\apiFlowAutoTest\venv\lib\site-packages\pymysql\connections.py", line 327, in __init__
    self.connect()
  File "E:\WorkZoom\apiFlowAutoTest\venv\lib\site-packages\pymysql\connections.py", line 619, in connect
    raise exc
pymysql.err.OperationalError: (2003, "Can't connect to MySQL server on 'rm-uf63c1mgv7c7b80a4.mysql.rds.aliyuncs.com' (timed out)")
2020-09-09 09:03:18,556 - root - ERROR : Error: 数据库连接时发生错误, 信息: (2003, "Can't connect to MySQL server on 'rm-uf63c1mgv7c7b80a4.mysql.rds.aliyuncs.com' (timed out)")
Traceback (most recent call last):
  File "E:\WorkZoom\apiFlowAutoTest\venv\lib\site-packages\pymysql\connections.py", line 571, in connect
    **kwargs)
  File "D:\Program Files\Python\lib\socket.py", line 728, in create_connection
    raise err
  File "D:\Program Files\Python\lib\socket.py", line 716, in create_connection
    sock.connect(sa)
socket.timeout: timed out

During handling of the above exception, another exception occurred:

Traceback (most recent call last):
  File "E:\WorkZoom\apiFlowAutoTest\common\config_db.py", line 23, in connect_db
    self.db = pymysql.connect(host=self.host, port=int(self.port), user=self.user, password=self.password)
  File "E:\WorkZoom\apiFlowAutoTest\venv\lib\site-packages\pymysql\__init__.py", line 94, in Connect
    return Connection(*args, **kwargs)
  File "E:\WorkZoom\apiFlowAutoTest\venv\lib\site-packages\pymysql\connections.py", line 327, in __init__
    self.connect()
  File "E:\WorkZoom\apiFlowAutoTest\venv\lib\site-packages\pymysql\connections.py", line 619, in connect
    raise exc
pymysql.err.OperationalError: (2003, "Can't connect to MySQL server on 'rm-uf63c1mgv7c7b80a4.mysql.rds.aliyuncs.com' (timed out)")
2020-09-09 09:03:28,649 - root - ERROR : Error: 数据库连接时发生错误, 信息: (2003, "Can't connect to MySQL server on 'rm-uf63c1mgv7c7b80a4.mysql.rds.aliyuncs.com' (timed out)")
Traceback (most recent call last):
  File "E:\WorkZoom\apiFlowAutoTest\venv\lib\site-packages\pymysql\connections.py", line 571, in connect
    **kwargs)
  File "D:\Program Files\Python\lib\socket.py", line 728, in create_connection
    raise err
  File "D:\Program Files\Python\lib\socket.py", line 716, in create_connection
    sock.connect(sa)
socket.timeout: timed out

During handling of the above exception, another exception occurred:

Traceback (most recent call last):
  File "E:\WorkZoom\apiFlowAutoTest\common\config_db.py", line 23, in connect_db
    self.db = pymysql.connect(host=self.host, port=int(self.port), user=self.user, password=self.password)
  File "E:\WorkZoom\apiFlowAutoTest\venv\lib\site-packages\pymysql\__init__.py", line 94, in Connect
    return Connection(*args, **kwargs)
  File "E:\WorkZoom\apiFlowAutoTest\venv\lib\site-packages\pymysql\connections.py", line 327, in __init__
    self.connect()
  File "E:\WorkZoom\apiFlowAutoTest\venv\lib\site-packages\pymysql\connections.py", line 619, in connect
    raise exc
pymysql.err.OperationalError: (2003, "Can't connect to MySQL server on 'rm-uf63c1mgv7c7b80a4.mysql.rds.aliyuncs.com' (timed out)")
2020-09-09 09:03:38,713 - root - ERROR : Error: 数据库连接时发生错误, 信息: (2003, "Can't connect to MySQL server on 'rm-uf63c1mgv7c7b80a4.mysql.rds.aliyuncs.com' (timed out)")
Traceback (most recent call last):
  File "E:\WorkZoom\apiFlowAutoTest\venv\lib\site-packages\pymysql\connections.py", line 571, in connect
    **kwargs)
  File "D:\Program Files\Python\lib\socket.py", line 728, in create_connection
    raise err
  File "D:\Program Files\Python\lib\socket.py", line 716, in create_connection
    sock.connect(sa)
socket.timeout: timed out

During handling of the above exception, another exception occurred:

Traceback (most recent call last):
  File "E:\WorkZoom\apiFlowAutoTest\common\config_db.py", line 23, in connect_db
    self.db = pymysql.connect(host=self.host, port=int(self.port), user=self.user, password=self.password)
  File "E:\WorkZoom\apiFlowAutoTest\venv\lib\site-packages\pymysql\__init__.py", line 94, in Connect
    return Connection(*args, **kwargs)
  File "E:\WorkZoom\apiFlowAutoTest\venv\lib\site-packages\pymysql\connections.py", line 327, in __init__
    self.connect()
  File "E:\WorkZoom\apiFlowAutoTest\venv\lib\site-packages\pymysql\connections.py", line 619, in connect
    raise exc
pymysql.err.OperationalError: (2003, "Can't connect to MySQL server on 'rm-uf63c1mgv7c7b80a4.mysql.rds.aliyuncs.com' (timed out)")
2020-09-09 09:03:48,826 - root - ERROR : Error: 数据库连接时发生错误, 信息: (2003, "Can't connect to MySQL server on 'rm-uf63c1mgv7c7b80a4.mysql.rds.aliyuncs.com' (timed out)")
Traceback (most recent call last):
  File "E:\WorkZoom\apiFlowAutoTest\venv\lib\site-packages\pymysql\connections.py", line 571, in connect
    **kwargs)
  File "D:\Program Files\Python\lib\socket.py", line 728, in create_connection
    raise err
  File "D:\Program Files\Python\lib\socket.py", line 716, in create_connection
    sock.connect(sa)
socket.timeout: timed out

During handling of the above exception, another exception occurred:

Traceback (most recent call last):
  File "E:\WorkZoom\apiFlowAutoTest\common\config_db.py", line 23, in connect_db
    self.db = pymysql.connect(host=self.host, port=int(self.port), user=self.user, password=self.password)
  File "E:\WorkZoom\apiFlowAutoTest\venv\lib\site-packages\pymysql\__init__.py", line 94, in Connect
    return Connection(*args, **kwargs)
  File "E:\WorkZoom\apiFlowAutoTest\venv\lib\site-packages\pymysql\connections.py", line 327, in __init__
    self.connect()
  File "E:\WorkZoom\apiFlowAutoTest\venv\lib\site-packages\pymysql\connections.py", line 619, in connect
    raise exc
pymysql.err.OperationalError: (2003, "Can't connect to MySQL server on 'rm-uf63c1mgv7c7b80a4.mysql.rds.aliyuncs.com' (timed out)")
2020-09-09 09:03:58,884 - root - ERROR : Error: 数据库连接时发生错误, 信息: (2003, "Can't connect to MySQL server on 'rm-uf63c1mgv7c7b80a4.mysql.rds.aliyuncs.com' (timed out)")
Traceback (most recent call last):
  File "E:\WorkZoom\apiFlowAutoTest\venv\lib\site-packages\pymysql\connections.py", line 571, in connect
    **kwargs)
  File "D:\Program Files\Python\lib\socket.py", line 728, in create_connection
    raise err
  File "D:\Program Files\Python\lib\socket.py", line 716, in create_connection
    sock.connect(sa)
socket.timeout: timed out

During handling of the above exception, another exception occurred:

Traceback (most recent call last):
  File "E:\WorkZoom\apiFlowAutoTest\common\config_db.py", line 23, in connect_db
    self.db = pymysql.connect(host=self.host, port=int(self.port), user=self.user, password=self.password)
  File "E:\WorkZoom\apiFlowAutoTest\venv\lib\site-packages\pymysql\__init__.py", line 94, in Connect
    return Connection(*args, **kwargs)
  File "E:\WorkZoom\apiFlowAutoTest\venv\lib\site-packages\pymysql\connections.py", line 327, in __init__
    self.connect()
  File "E:\WorkZoom\apiFlowAutoTest\venv\lib\site-packages\pymysql\connections.py", line 619, in connect
    raise exc
pymysql.err.OperationalError: (2003, "Can't connect to MySQL server on 'rm-uf63c1mgv7c7b80a4.mysql.rds.aliyuncs.com' (timed out)")
2020-09-09 09:04:08,954 - root - ERROR : Error: 数据库连接时发生错误, 信息: (2003, "Can't connect to MySQL server on 'rm-uf63c1mgv7c7b80a4.mysql.rds.aliyuncs.com' (timed out)")
Traceback (most recent call last):
  File "E:\WorkZoom\apiFlowAutoTest\venv\lib\site-packages\pymysql\connections.py", line 571, in connect
    **kwargs)
  File "D:\Program Files\Python\lib\socket.py", line 728, in create_connection
    raise err
  File "D:\Program Files\Python\lib\socket.py", line 716, in create_connection
    sock.connect(sa)
socket.timeout: timed out

During handling of the above exception, another exception occurred:

Traceback (most recent call last):
  File "E:\WorkZoom\apiFlowAutoTest\common\config_db.py", line 23, in connect_db
    self.db = pymysql.connect(host=self.host, port=int(self.port), user=self.user, password=self.password)
  File "E:\WorkZoom\apiFlowAutoTest\venv\lib\site-packages\pymysql\__init__.py", line 94, in Connect
    return Connection(*args, **kwargs)
  File "E:\WorkZoom\apiFlowAutoTest\venv\lib\site-packages\pymysql\connections.py", line 327, in __init__
    self.connect()
  File "E:\WorkZoom\apiFlowAutoTest\venv\lib\site-packages\pymysql\connections.py", line 619, in connect
    raise exc
pymysql.err.OperationalError: (2003, "Can't connect to MySQL server on 'rm-uf63c1mgv7c7b80a4.mysql.rds.aliyuncs.com' (timed out)")
2020-09-09 09:04:19,016 - root - ERROR : Error: 数据库连接时发生错误, 信息: (2003, "Can't connect to MySQL server on 'rm-uf63c1mgv7c7b80a4.mysql.rds.aliyuncs.com' (timed out)")
Traceback (most recent call last):
  File "E:\WorkZoom\apiFlowAutoTest\venv\lib\site-packages\pymysql\connections.py", line 571, in connect
    **kwargs)
  File "D:\Program Files\Python\lib\socket.py", line 728, in create_connection
    raise err
  File "D:\Program Files\Python\lib\socket.py", line 716, in create_connection
    sock.connect(sa)
socket.timeout: timed out

During handling of the above exception, another exception occurred:

Traceback (most recent call last):
  File "E:\WorkZoom\apiFlowAutoTest\common\config_db.py", line 23, in connect_db
    self.db = pymysql.connect(host=self.host, port=int(self.port), user=self.user, password=self.password)
  File "E:\WorkZoom\apiFlowAutoTest\venv\lib\site-packages\pymysql\__init__.py", line 94, in Connect
    return Connection(*args, **kwargs)
  File "E:\WorkZoom\apiFlowAutoTest\venv\lib\site-packages\pymysql\connections.py", line 327, in __init__
    self.connect()
  File "E:\WorkZoom\apiFlowAutoTest\venv\lib\site-packages\pymysql\connections.py", line 619, in connect
    raise exc
pymysql.err.OperationalError: (2003, "Can't connect to MySQL server on 'rm-uf63c1mgv7c7b80a4.mysql.rds.aliyuncs.com' (timed out)")
